try {
  // perform an operation that may produce an error
} catch (exception) {
  // an error occurred. do something about it.
  // for example, log the error
} finally {
  // Optional 'finally' block; not used often
  // Executes regardless of whether an exception occurs.
}


// example
let names = ['bob', 'joe', 'steve', undefined, 'frank'];

names.forEach(name => {
  try {
    console.log(`${name}'s name has ${name.length} letters in it.`);
  } catch (exception) {
    console.log('Something went wrong');
  }
}); // => bob's name has 3 letters in it.
    //    joe's name has 3 letters in it.
    //    steve's name has 5 letters in it.
    //    Something went wrong
    //    frank's name has 5 letters in it.


// raise your own exceptions
    function foo(number) {
      if (typeof number !== "number") {
        throw new TypeError("expected a number");
      }
    
      // we're guaranteed to have a number here
    }